Workbook

Sheet Intake_Form
A1: Data Center Client Intake Form
A2: Use this sheet to structure messy early-stage client conversations into RFP-ready requirements. Yellow/blue fields are intended for user input.
A4: Section | B4: Field | C4: Value | D4: Unit | E4: Priority | F4: Status | G4: Notes / Open Questions | H4: Export_Key
A5: Client Profile | B5: Client / Company Name | E5: High | F5: Not Started | H5: client_name
A6: Client Profile | B6: Project Name | E6: High | F6: Not Started | H6: project_name
A7: Client Profile | B7: Primary Contact | E7: Medium | F7: Not Started | H7: primary_contact
A8: Client Profile | B8: Client Type / Use Case | E8: High | F8: Not Started | H8: use_case
A9: Client Profile | B9: Current Stage | E9: High | F9: Not Started | H9: project_stage
A10: Client Profile | B10: Target Decision Date | D10: date | E10: Medium | F10: Not Started | H10: target_decision_date
A11: Client Profile | B11: Decision Makers Identified? | E11: High | F11: Not Started | H11: decision_makers_identified
A12: Capacity Requirements | B12: Initial Critical IT Load | D12: MW | E12: Critical | F12: Not Started | H12: initial_critical_it_mw
A13: Capacity Requirements | B13: Future Expansion Requirement | D13: MW | E13: High | F13: Not Started | H13: future_expansion_mw
A14: Capacity Requirements | B14: Total Utility / Grid Load | D14: MW | E14: High | F14: Not Started | H14: total_utility_load_mw
A15: Capacity Requirements | B15: Ramp Schedule / Phasing | D15: text | E15: High | F15: Not Started | H15: ramp_schedule
A16: Capacity Requirements | B16: Minimum Viable Capacity | D16: MW | E16: Medium | F16: Not Started | H16: min_viable_capacity_mw
A17: Technical Requirements | B17: Rack Density Range | D17: kW/rack | E17: High | F17: Not Started | H17: rack_density
A18: Technical Requirements | B18: Cooling Requirement | D18: text | E18: Medium | F18: Not Started | H18: cooling_requirement
A19: Technical Requirements | B19: Redundancy Requirement | D19: text | E19: Medium | F19: Not Started | H19: redundancy_requirement
A20: Technical Requirements | B20: Latency / Connectivity Requirements | D20: text | E20: Medium | F20: Not Started | H20: connectivity_requirements
A21: Technical Requirements | B21: Security / Compliance Requirements | D21: text | E21: Medium | F21: Not Started | H21: security_compliance
A22: Market Preferences | B22: Preferred Markets | D22: text | E22: High | F22: Not Started | H22: preferred_markets
A23: Market Preferences | B23: Acceptable Regions | D23: text | E23: Medium | F23: Not Started | H23: acceptable_regions
A24: Market Preferences | B24: Markets to Avoid | D24: text | E24: Low | F24: Not Started | H24: markets_to_avoid
A25: Market Preferences | B25: Latency-Driven Constraints? | E25: Medium | F25: Not Started | H25: latency_constraints
A26: Market Preferences | B26: Tax / Incentive Sensitivity | D26: text | E26: Low | F26: Not Started | H26: tax_incentive_sensitivity
A27: Power Requirements | B27: Required Power Delivery Date | D27: date | E27: Critical | F27: Not Started | H27: power_delivery_date
A28: Power Requirements | B28: Power Source Preference | D28: text | E28: Medium | F28: Not Started | H28: power_source_preference
A29: Power Requirements | B29: Renewable / Carbon Requirements | D29: text | E29: Medium | F29: Not Started | H29: renewable_requirements
A30: Power Requirements | B30: Utility / Interconnection Status | D30: text | E30: High | F30: Not Started | H30: interconnection_status
A31: Power Requirements | B31: Tolerance for Power Delay | D31: months | E31: High | F31: Not Started | H31: power_delay_tolerance
A32: Supply Chain | B32: Long-Lead Equipment Known? | E32: High | F32: Not Started | H32: long_lead_equipment_known
A33: Supply Chain | B33: Transformer / Switchgear Needs | D33: text | E33: High | F33: Not Started | H33: transformer_switchgear_needs
A34: Supply Chain | B34: Generator / Cooling Procurement | D34: text | E34: Medium | F34: Not Started | H34: generator_cooling_procurement
A35: Supply Chain | B35: Procurement Responsibility | D35: text | E35: Medium | F35: Not Started | H35: procurement_responsibility
A36: Commercial / Deal Model | B36: Preferred Commercial Model | E36: Critical | F36: Not Started | H36: commercial_model
A37: Commercial / Deal Model | B37: Lease Term / Contract Term | D37: years | E37: High | F37: Not Started | H37: lease_contract_term
A38: Commercial / Deal Model | B38: Budget / Pricing Tolerance | D38: $/kW-mo or $/MW | E38: High | F38: Not Started | H38: budget_pricing_tolerance
A39: Commercial / Deal Model | B39: Lease vs Buy Decision Made? | E39: Critical | F39: Not Started | H39: lease_vs_buy_decision
A40: Commercial / Deal Model | B40: Capital / Financing Status | D40: text | E40: High | F40: Not Started | H40: capital_financing_status
A41: RFP / CBRE Readiness | B41: Is Client Ready for CBRE Market Process? | E41: Critical | F41: Not Started | H41: ready_for_cbre
...

Sheet Readiness_Scorecard
A1: RFP Readiness Scorecard
A2: Score each category from 1 to 5. Weighted score calculates readiness. Use the gap/action columns to turn unclear client situations into consulting work.
A4: Category | B4: Score (1-5) | C4: Weight | D4: Weighted Score | E4: Current Evidence | F4: Gap | G4: Recommended Action | H4: Owner | J4: Summary
A5: Capacity clarity | C5: 15 | D5: =IF(OR(B5="",C5=""),"",B5/5*C5) | J5: Overall Readiness Score | K5: =SUM(D5:D12) -> 0 | L5: /100
A6: Timeline clarity | C6: 15 | D6: =IF(OR(B6="",C6=""),"",B6/5*C6) | J6: Average Category Score | K6: =AVERAGE(B5:B12) -> #DIV/0! | L6: /5
A7: Technical specs | C7: 12 | D7: =IF(OR(B7="",C7=""),"",B7/5*C7) | J7: Readiness Status | K7: =IF(K5="","",IF(K5>=80,"RFP-ready",IF(K5>=65,"Mostly ready",IF(K5>=45,"Needs structuring","Not ready")))) -> Not ready
A8: Market clarity | C8: 10 | D8: =IF(OR(B8="",C8=""),"",B8/5*C8) | J8: Top Gap Count | K8: =COUNTIF(B5:B12,"<=2") -> 0 | L8: categories at 1-2
A9: Power strategy | C9: 18 | D9: =IF(OR(B9="",C9=""),"",B9/5*C9) | J9: Next Review Date | K9: =IF(Intake_Form!C10="",TODAY()+30,Intake_Form!C10) -> 46183 | L9: date
A10: Commercial model | C10: 12 | D10: =IF(OR(B10="",C10=""),"",B10/5*C10)
A11: Capital readiness | C11: 10 | D11: =IF(OR(B11="",C11=""),"",B11/5*C11)
A12: Decision alignment | C12: 8 | D12: =IF(OR(B12="",C12=""),"",B12/5*C12)

Sheet RFP_Requirement_Sheet
A1: RFP-Ready Requirement Sheet
A2: Client-facing summary generated from Intake_Form and Readiness_Scorecard. Use as a draft handoff before a formal CBRE market process.
A4: Client / Project
A5: Client Name | C5: =Intake_Form!C5 -> 0
A6: Project Name | C6: =Intake_Form!C6 -> 0
A7: Use Case | C7: =Intake_Form!C8 -> 0
A8: Current Stage | C8: =Intake_Form!C9 -> 0
A10: Capacity & Timeline
A11: Initial Critical IT Load | C11: =Intake_Form!C12 -> 0
A12: Future Expansion Requirement | C12: =Intake_Form!C13 -> 0
A13: Total Utility / Grid Load | C13: =Intake_Form!C14 -> 0
A14: Ramp Schedule | C14: =Intake_Form!C15 -> 0
A15: Target Decision Date | C15: =Intake_Form!C10 -> 0
A17: Technical Requirements
A18: Rack Density | C18: =Intake_Form!C17 -> 0
A19: Cooling Requirement | C19: =Intake_Form!C18 -> 0
A20: Redundancy Requirement | C20: =Intake_Form!C19 -> 0
A21: Connectivity / Fiber | C21: =Intake_Form!C20 -> 0
A22: Security / Compliance | C22: =Intake_Form!C21 -> 0
A24: Market & Power
A25: Preferred Markets | C25: =Intake_Form!C22 -> 0
A26: Acceptable Regions | C26: =Intake_Form!C23 -> 0
A27: Required Power Delivery Date | C27: =Intake_Form!C27 -> 0
A28: Interconnection Status | C28: =Intake_Form!C30 -> 0
A29: Power Delay Tolerance | C29: =Intake_Form!C31 -> 0
A31: Commercial Model
A32: Preferred Commercial Model | C32: =Intake_Form!C36 -> 0
A33: Lease / Contract Term | C33: =Intake_Form!C37 -> 0
A34: Budget / Pricing Tolerance | C34: =Intake_Form!C38 -> 0
A35: Lease vs Buy Decision Made? | C35: =Intake_Form!C39 -> 0
A36: Capital / Financing Status | C36: =Intake_Form!C40 -> 0
A38: Readiness & Next Steps
A39: Readiness Score | C39: =Readiness_Scorecard!K5 -> 0
A40: Readiness Status | C40: =Readiness_Scorecard!K7 -> Not ready
A41: Key Gaps Before RFP | C41: =Intake_Form!C42 -> 0
A42: Recommended Next Step | C42: =Intake_Form!C43 -> 0

Sheet PowerBI_Export
A1: date | B1: project_id | C1: category | D1: market | E1: requirement_name | F1: status | G1: severity | H1: notes

Sheet Lists
A1: Status | B1: Project Stage | C1: Use Case | D1: Commercial Model | E1: Priority | F1: Yes/No/Unknown | G1: Readiness Rating | H1: Risk Level | J1: Category | K1: Score 1 | L1: Score 3 | M1: Score 5 | N1: Weight
A2: Not Started | B2: Exploring | C2: AI Training | D2: Colocation | E2: Low | F2: Yes | G2: 1 - Very unclear | H2: Low | J2: Capacity clarity | K2: Unclear MW / no phase plan | L2: Approximate MW known | M2: Initial and expansion MW clearly phased | N2: 15
A3: In Progress | B3: Requirement Definition | C3: AI Inference | D3: Wholesale Lease | E3: Medium | F3: No | G3: 2 - Weak | H3: Medium | J3: Timeline clarity | K3: No go-live date | L3: Target window only | M3: Delivery dates and ramp milestones defined | N3: 15
A4: Complete | B4: RFP Prep | C4: HPC | D4: NNN Lease | E4: High | F4: Unknown | G4: 3 - Partial | H4: High | J4: Technical specs | K4: Minimal technical detail | L4: Some rack/cooling/redundancy detail | M4: Complete technical requirements documented | N4: 12
A5: Needs Follow-up | B5: Active RFP | C5: Cloud | D5: Build-to-Suit | E5: Critical | F5: TBD | G5: 4 - Mostly ready | H5: Critical | J5: Market clarity | K5: Markets not narrowed | L5: Preferred regions identified | M5: Realistic market shortlist defined | N5: 10
A6: Not Applicable | B6: Negotiation | C6: Enterprise IT | D6: Powered Land | G6: 5 - RFP-ready | H6: Unknown | J6: Power strategy | K6: No power plan | L6: Basic power needs stated | M6: Power, interconnection, energy preferences clear | N6: 18
B7: Board Approval | C7: Colocation | D7: Buy-Own-Operate | J7: Commercial model | K7: No preferred model | L7: Some lease/buy preference | M7: Commercial structure and budget defined | N7: 12
B8: Closed/Won | C8: Disaster Recovery | D8: Joint Venture | J8: Capital readiness | K8: Capital source unclear | L8: Funding path in discussion | M8: Funding, credit, approval path clear | N8: 10
B9: Paused | C9: Crypto/Mining | D9: Undecided | J9: Decision alignment | K9: No decision-maker alignment | L9: Some stakeholders identified | M9: Decision-makers, approval process, and next steps clear | N9: 8
C10: Other

Sheet Client_Export
A1: assessment_date | B1: project_id | C1: client_name | D1: project_name | E1: primary_contact | F1: use_case | G1: project_stage | H1: target_decision_date | I1: decision_makers_identified | J1: initial_critical_it_mw | K1: future_expansion_mw | L1: total_utility_load_mw | M1: ramp_schedule | N1: min_viable_capacity_mw | O1: rack_density | P1: cooling_requirement | Q1: redundancy_requirement | R1: connectivity_requirements | S1: security_compliance | T1: preferred_markets | U1: acceptable_regions | V1: markets_to_avoid | W1: latency_constraints | X1: tax_incentive_sensitivity | Y1: power_delivery_date | Z1: power_source_preference | AA1: renewable_requirements | AB1: interconnection_status | AC1: power_delay_tolerance | AD1: long_lead_equipment_known | AE1: transformer_switchgear_needs | AF1: generator_cooling_procurement | AG1: procurement_responsibility | AH1: commercial_model | AI1: lease_contract_term | AJ1: budget_pricing_tolerance | AK1: lease_vs_buy_decision | AL1: capital_financing_status | AM1: ready_for_cbre | AN1: key_gaps_before_rfp | AO1: recommended_next_step
A2: =IF(Intake_Form!C10="",TODAY(),Intake_Form!C10) -> 46153 | B2: =IF(Intake_Form!C6="","",UPPER(SUBSTITUTE(LEFT(Intake_Form!C6,18)," ","_"))) | C2: =Intake_Form!C5 -> 0 | D2: =Intake_Form!C6 -> 0 | E2: =Intake_Form!C7 -> 0 | F2: =Intake_Form!C8 -> 0 | G2: =Intake_Form!C9 -> 0 | H2: =Intake_Form!C10 -> 0 | I2: =Intake_Form!C11 -> 0 | J2: =Intake_Form!C12 -> 0 | K2: =Intake_Form!C13 -> 0 | L2: =Intake_Form!C14 -> 0 | M2: =Intake_Form!C15 -> 0 | N2: =Intake_Form!C16 -> 0 | O2: =Intake_Form!C17 -> 0 | P2: =Intake_Form!C18 -> 0 | Q2: =Intake_Form!C19 -> 0 | R2: =Intake_Form!C20 -> 0 | S2: =Intake_Form!C21 -> 0 | T2: =Intake_Form!C22 -> 0 | U2: =Intake_Form!C23 -> 0 | V2: =Intake_Form!C24 -> 0 | W2: =Intake_Form!C25 -> 0 | X2: =Intake_Form!C26 -> 0 | Y2: =Intake_Form!C27 -> 0 | Z2: =Intake_Form!C28 -> 0 | AA2: =Intake_Form!C29 -> 0 | AB2: =Intake_Form!C30 -> 0 | AC2: =Intake_Form!C31 -> 0 | AD2: =Intake_Form!C32 -> 0 | AE2: =Intake_Form!C33 -> 0 | AF2: =Intake_Form!C34 -> 0 | AG2: =Intake_Form!C35 -> 0 | AH2: =Intake_Form!C36 -> 0 | AI2: =Intake_Form!C37 -> 0 | AJ2: =Intake_Form!C38 -> 0 | AK2: =Intake_Form!C39 -> 0 | AL2: =Intake_Form!C40 -> 0 | AM2: =Intake_Form!C41 -> 0 | AN2: =Intake_Form!C42 -> 0 | AO2: =Intake_Form!C43 -> 0

Sheet Requirement_Map
A1: requirement_id | B1: requirement_name | C1: category | D1: severity | E1: intake_field | F1: answer_yes_status | G1: answer_no_status | H1: answer_partial_status | I1: default_status | J1: default_notes | K1: market_scope
A2: REQ-001 | B2: Phase 1 MW requirement defined | C2: capacity | D2: high | E2: initial_critical_it_mw | F2: complete | G2: open | H2: in_progress | I2: complete | J2: 32 MW Phase 1 confirmed | K2: NAM-NOVA
A3: REQ-002 | B3: Phase 2 expansion scope | C3: capacity | D3: medium | E3: future_expansion_mw | F3: complete | G3: open | H3: in_progress | I3: in_progress | J3: Phase 2 sizing under review | K3: NAM-NOVA
A4: REQ-003 | B4: Minimum viable capacity confirmed | C4: capacity | D4: critical | E4: min_viable_capacity_mw | F4: complete | G4: not_started | H4: in_progress | I4: not_started | J4: No confirmation from tech team | K4: NAM-PHX
A5: REQ-004 | B5: Go-live delivery date set | C5: timeline | D5: high | E5: target_decision_date | F5: complete | G5: open | H5: in_progress | I5: complete | J5: Q2 2026 target confirmed | K5: NAM-NOVA
A6: REQ-005 | B6: Ramp milestone schedule defined | C6: timeline | D6: high | E6: ramp_schedule | F6: complete | G6: open | H6: in_progress | I6: complete | J6: Three-phase ramp agreed | K6: NAM-PHX
A7: REQ-006 | B7: Target decision date confirmed | C7: timeline | D7: medium | E7: target_decision_date | F7: complete | G7: open | H7: in_progress | I7: complete | J7: October 2025 decision date | K7: NAM-CHI
A8: REQ-007 | B8: Rack density specification documented | C8: technical | D8: high | E8: rack_density | F8: complete | G8: open | H8: in_progress | I8: complete | J8: 20 kW/rack average | K8: NAM-NOVA
A9: REQ-008 | B9: Cooling and redundancy requirements set | C9: technical | D9: medium | E9: cooling_requirement | F9: complete | G9: open | H9: in_progress | I9: complete | J9: N+1 cooling, 2N power | K9: NAM-NOVA
A10: REQ-009 | B10: Security and compliance requirements | C10: technical | D10: high | E10: security_compliance | F10: complete | G10: open | H10: in_progress | I10: in_progress | J10: SOC 2 assessment ongoing | K10: NAM-PHX
A11: REQ-010 | B11: Primary market shortlist defined | C11: market | D11: high | E11: preferred_markets | F11: complete | G11: open | H11: in_progress | I11: complete | J11: NOVA primary, PHX secondary | K11: NAM-NOVA
A12: REQ-011 | B12: Secondary market preferences confirmed | C12: market | D12: medium | E12: acceptable_regions | F12: complete | G12: open | H12: in_progress | I12: complete | J12: PHX confirmed as backup | K12: NAM-PHX
... A23: REQ-022 | B23: Decision makers identified | C23: decision | D23: high | E23: decision_makers_identified | F23: complete | G23: open | H23: in_progress | I23: complete | J23: CTO and CFO confirmed as sponsors | K23: NAM-NOVA
A24: REQ-023 | B24: Approval process defined | C24: decision | D24: medium | F24: complete | G24: open | H24: in_progress | I24: complete | J24: Standard procurement sign-off | K24: NAM-NOVA
A25: REQ-024 | B25: Stakeholder alignment confirmed | C25: decision | D25: high | E25: ready_for_cbre | F25: complete | G25: open | H25: in_progress | I25: open | J25: Regional team not yet briefed | K25: NAM-PHX
