Workbook

Sheet README
A1: Data Center RFP Readiness Toolkit - Client Intake Template
A3: Purpose
A4: Reusable intake workbook for turning early-stage data center occupier / AI infrastructure conversations into structured requirements, readiness scoring, and RFP-ready outputs. Designed as a first prototype for consulting workflow.
A8: Sheet | B8: Role | C8: Primary User | D8: Output | E8: Feeds Power BI? | F8: Notes
A9: Intake_Form | B9: Capture raw client/project requirements | C9: Me + Dave during/after meetings | D9: Structured client requirement record | E9: Yes | F9: Main editable sheet
A10: Readiness_Scorecard | B10: Score client readiness and identify gaps | C10: Me + Dave | D10: Overall readiness status and gap analysis | E10: Yes | F10: Formula-driven summary
A11: RFP_Requirement_Sheet | B11: Convert intake into an RFP-ready brief | C11: Dave/client-facing | D11: Clean requirement sheet | E11: Partial | F11: Copy/paste into memo or proposal
A12: PowerBI_Export | B12: Normalize data for dashboards/reporting | C12: Power BI / analytics pipeline | D12: Long-form key-value table | E12: Yes | F12: Stable schema for future automation
A13: Lists | B13: Dropdowns and scoring rubric | C13: Admin only | D13: Controlled values | E13: Yes | F13: Expand lists without redesigning workbook
A15: Recommended workflow
A16: 1 | B16: Complete Intake_Form after each client conversation.
A17: 2 | B17: Review Readiness_Scorecard to identify gaps and next steps.
A18: 3 | B18: Use RFP_Requirement_Sheet as the meeting summary / CBRE-ready handoff draft.
A19: 4 | B19: Use PowerBI_Export as the stable data layer for dashboards later.
A20: 5 | B20: Keep Lists updated as the consulting platform becomes more mature.
B21: North star: clean intake → trusted readiness score → RFP-ready output → visuals anywhere.

Sheet Intake_Form
A1: Data Center Client Intake Form
A2: Use this sheet to structure messy early-stage client conversations into RFP-ready requirements. Yellow/blue fields are intended for user input.
A4: Section | B4: Field | C4: Value | D4: Unit | E4: Priority | F4: Status | G4: Notes / Open Questions | H4: Export_Key
A5: Client Profile | B5: Client / Company Name | E5: High | F5: Not Started | H5: client_name
A6: Client Profile | B6: Project Name | E6: High | F6: Not Started | H6: project_name
A7: Client Profile | B7: Primary Contact | E7: Medium | F7: Not Started | H7: primary_contact
A8: Client Profile | B8: Client Type / Use Case | E8: High | F8: Not Started | H8: use_case
A9: Client Profile | B9: Current Stage | E9: High | F9: Not Started | H9: project_stage
A10: Client Profile | B10: Target Decision Date | D10: date | E10: Medium | F10: Not Started | H10: target_decision_date
A11: Client Profile | B11: Decision Makers Identified? | E11: High | F11: Not Started | H11: decision_makers_identified
A12: Capacity Requirements | B12: Initial Critical IT Load | D12: MW | E12: Critical | F12: Not Started | H12: initial_critical_it_mw
A13: Capacity Requirements | B13: Future Expansion Requirement | D13: MW | E13: High | F13: Not Started | H13: future_expansion_mw
A14: Capacity Requirements | B14: Total Utility / Grid Load | D14: MW | E14: High | F14: Not Started | H14: total_utility_load_mw
A15: Capacity Requirements | B15: Ramp Schedule / Phasing | D15: text | E15: High | F15: Not Started | H15: ramp_schedule
A16: Capacity Requirements | B16: Minimum Viable Capacity | D16: MW | E16: Medium | F16: Not Started | H16: min_viable_capacity_mw
A17: Technical Requirements | B17: Rack Density Range | D17: kW/rack | E17: High | F17: Not Started | H17: rack_density
A18: Technical Requirements | B18: Cooling Requirement | D18: text | E18: Medium | F18: Not Started | H18: cooling_requirement
A19: Technical Requirements | B19: Redundancy Requirement | D19: text | E19: Medium | F19: Not Started | H19: redundancy_requirement
A20: Technical Requirements | B20: Latency / Connectivity Requirements | D20: text | E20: Medium | F20: Not Started | H20: connectivity_requirements
A21: Technical Requirements | B21: Security / Compliance Requirements | D21: text | E21: Medium | F21: Not Started | H21: security_compliance
A22: Market Preferences | B22: Preferred Markets | D22: text | E22: High | F22: Not Started | H22: preferred_markets
A23: Market Preferences | B23: Acceptable Regions | D23: text | E23: Medium | F23: Not Started | H23: acceptable_regions
A24: Market Preferences | B24: Markets to Avoid | D24: text | E24: Low | F24: Not Started | H24: markets_to_avoid
A25: Market Preferences | B25: Latency-Driven Constraints? | E25: Medium | F25: Not Started | H25: latency_constraints
A26: Market Preferences | B26: Tax / Incentive Sensitivity | D26: text | E26: Low | F26: Not Started | H26: tax_incentive_sensitivity
A27: Power Requirements | B27: Required Power Delivery Date | D27: date | E27: Critical | F27: Not Started | H27: power_delivery_date
A28: Power Requirements | B28: Power Source Preference | D28: text | E28: Medium | F28: Not Started | H28: power_source_preference
A29: Power Requirements | B29: Renewable / Carbon Requirements | D29: text | E29: Medium | F29: Not Started | H29: renewable_requirements
A30: Power Requirements | B30: Utility / Interconnection Status | D30: text | E30: High | F30: Not Started | H30: interconnection_status
A31: Power Requirements | B31: Tolerance for Power Delay | D31: months | E31: High | F31: Not Started | H31: power_delay_tolerance
A32: Supply Chain | B32: Long-Lead Equipment Known? | E32: High | F32: Not Started | H32: long_lead_equipment_known
A33: Supply Chain | B33: Transformer / Switchgear Needs | D33: text | E33: High | F33: Not Started | H33: transformer_switchgear_needs
A34: Supply Chain | B34: Generator / Cooling Procurement | D34: text | E34: Medium | F34: Not Started | H34: generator_cooling_procurement
A35: Supply Chain | B35: Procurement Responsibility | D35: text | E35: Medium | F35: Not Started | H35: procurement_responsibility
A36: Commercial / Deal Model | B36: Preferred Commercial Model | E36: Critical | F36: Not Started | H36: commercial_model
A37: Commercial / Deal Model | B37: Lease Term / Contract Term | D37: years | E37: High | F37: Not Started | H37: lease_contract_term
A38: Commercial / Deal Model | B38: Budget / Pricing Tolerance | D38: $/kW-mo or $/MW | E38: High | F38: Not Started | H38: budget_pricing_tolerance
A39: Commercial / Deal Model | B39: Lease vs Buy Decision Made? | E39: Critical | F39: Not Started | H39: lease_vs_buy_decision
A40: Commercial / Deal Model | B40: Capital / Financing Status | D40: text | E40: High | F40: Not Started | H40: capital_financing_status
A41: RFP / CBRE Readiness | B41: Is Client Ready for CBRE Market Process? | E41: Critical | F41: Not Started | H41: ready_for_cbre
...

Sheet Readiness_Scorecard
A1: RFP Readiness Scorecard
A2: Score each category from 1 to 5. Weighted score calculates readiness. Use the gap/action columns to turn unclear client situations into consulting work.
A4: Category | B4: Score (1-5) | C4: Weight | D4: Weighted Score | E4: Current Evidence | F4: Gap | G4: Recommended Action | H4: Owner | J4: Summary
A5: Capacity clarity | B5: 1 | C5: 15 | D5: =IFERROR(B5*C5/5,0) | J5: Overall Readiness Score | K5: =SUM(D5:D12) | L5: /100
A6: Timeline clarity | B6: 5 | C6: 15 | D6: =IFERROR(B6*C6/5,0) | J6: Average Category Score | K6: =IFERROR(AVERAGE(B5:B12),"") | L6: /5
A7: Technical specs | B7: 5 | C7: 12 | D7: =IFERROR(B7*C7/5,0) | J7: Readiness Status | K7: =IF(K5<40,"Not Ready",IF(K5<65,"Needs Structuring",IF(K5<80,"Nearly RFP-Ready","RFP-Ready")))
A8: Market clarity | B8: 5 | C8: 10 | D8: =IFERROR(B8*C8/5,0) | J8: Top Gap Count | K8: =COUNTIFS(B5:B12,">=1",B5:B12,"<=2") | L8: categories at 1-2
A9: Power strategy | B9: 5 | C9: 18 | D9: =IFERROR(B9*C9/5,0) | J9: Next Review Date | L9: date
A10: Commercial model | B10: 4 | C10: 12 | D10: =IFERROR(B10*C10/5,0)
A11: Capital readiness | B11: 4 | C11: 10 | D11: =IFERROR(B11*C11/5,0)
A12: Decision alignment | B12: 4 | C12: 8 | D12: =IFERROR(B12*C12/5,0)

Sheet RFP_Requirement_Sheet
A1: RFP-Ready Requirement Sheet
A2: Client-facing summary generated from Intake_Form and Readiness_Scorecard. Use as a draft handoff before a formal CBRE market process.
A4: Client / Project
A5: Client Name | C5: =Intake_Form!C5
A6: Project Name | C6: =Intake_Form!C6
A7: Use Case | C7: =Intake_Form!C8
A8: Current Stage | C8: =Intake_Form!C9
A10: Capacity & Timeline
A11: Initial Critical IT Load | C11: =Intake_Form!C12
A12: Future Expansion Requirement | C12: =Intake_Form!C13
A13: Total Utility / Grid Load | C13: =Intake_Form!C14
A14: Ramp Schedule | C14: =Intake_Form!C15
A15: Target Decision Date | C15: =Intake_Form!C10
A17: Technical Requirements
A18: Rack Density | C18: =Intake_Form!C17
A19: Cooling Requirement | C19: =Intake_Form!C18
A20: Redundancy Requirement | C20: =Intake_Form!C19
A21: Connectivity / Fiber | C21: =Intake_Form!C20
A22: Security / Compliance | C22: =Intake_Form!C21
A24: Market & Power
A25: Preferred Markets | C25: =Intake_Form!C22
A26: Acceptable Regions | C26: =Intake_Form!C23
A27: Required Power Delivery Date | C27: =Intake_Form!C27
A28: Interconnection Status | C28: =Intake_Form!C30
A29: Power Delay Tolerance | C29: =Intake_Form!C31
A31: Commercial Model
A32: Preferred Commercial Model | C32: =Intake_Form!C36
A33: Lease / Contract Term | C33: =Intake_Form!C37
A34: Budget / Pricing Tolerance | C34: =Intake_Form!C38
A35: Lease vs Buy Decision Made? | C35: =Intake_Form!C39
A36: Capital / Financing Status | C36: =Intake_Form!C40
A38: Readiness & Next Steps
A39: Readiness Score | C39: =Readiness_Scorecard!K5
A40: Readiness Status | C40: =Readiness_Scorecard!K7
A41: Key Gaps Before RFP | C41: =Intake_Form!C42
A42: Recommended Next Step | C42: =Intake_Form!C43

Sheet PowerBI_Export
A1: date | B1: project_id | C1: category | D1: market | E1: requirement_name | F1: status | G1: severity | H1: notes
A2: 45915 | B2: NVT-2025-NAM | C2: capacity | D2: NAM-NOVA | E2: Phase 1 MW requirement defined | F2: complete | G2: high | H2: 32 MW Phase 1 confirmed
A3: 45915 | B3: NVT-2025-NAM | C3: capacity | D3: NAM-NOVA | E3: Phase 2 expansion scope | F3: in_progress | G3: medium | H3: Phase 2 sizing under review
A4: 45915 | B4: NVT-2025-NAM | C4: capacity | D4: NAM-PHX | E4: Minimum viable capacity confirmed | F4: not_started | G4: critical | H4: No confirmation from tech team
A5: 45915 | B5: NVT-2025-NAM | C5: timeline | D5: NAM-NOVA | E5: Go-live delivery date set | F5: complete | G5: high | H5: Q2 2026 target confirmed
A6: 45915 | B6: NVT-2025-NAM | C6: timeline | D6: NAM-PHX | E6: Ramp milestone schedule defined | F6: complete | G6: high | H6: Three-phase ramp agreed
A7: 45915 | B7: NVT-2025-NAM | C7: timeline | D7: NAM-CHI | E7: Target decision date confirmed | F7: complete | G7: medium | H7: October 2025 decision date
A8: 45915 | B8: NVT-2025-NAM | C8: technical | D8: NAM-NOVA | E8: Rack density specification documented | F8: complete | G8: high | H8: 20 kW/rack average
A9: 45915 | B9: NVT-2025-NAM | C9: technical | D9: NAM-NOVA | E9: Cooling and redundancy requirements set | F9: complete | G9: medium | H9: N+1 cooling, 2N power
A10: 45915 | B10: NVT-2025-NAM | C10: technical | D10: NAM-PHX | E10: Security and compliance requirements | F10: in_progress | G10: high | H10: SOC 2 assessment ongoing
A11: 45915 | B11: NVT-2025-NAM | C11: market | D11: NAM-NOVA | E11: Primary market shortlist defined | F11: complete | G11: high | H11: NOVA primary, PHX secondary
A12: 45915 | B12: NVT-2025-NAM | C12: market | D12: NAM-PHX | E12: Secondary market preferences confirmed | F12: complete | G12: medium | H12: PHX confirmed as backup
A13: 45915 | B13: NVT-2025-NAM | C13: market | D13: NAM-CHI | E13: Markets-to-avoid constraints documented | F13: complete | G13: low | H13: EU excluded on latency grounds
... A25: 45915 | B25: NVT-2025-NAM | C25: decision | D25: NAM-PHX | E25: Stakeholder alignment confirmed | F25: open | G25: high | H25: Regional team not yet briefed

Sheet Lists
A1: Status | B1: Project Stage | C1: Use Case | D1: Commercial Model | E1: Priority | F1: Yes/No/Unknown | G1: Readiness Rating | H1: Risk Level | J1: Category | K1: Score 1 | L1: Score 3 | M1: Score 5 | N1: Weight
A2: Not Started | B2: Exploring | C2: AI Training | D2: Colocation | E2: Low | F2: Yes | G2: 1 - Very unclear | H2: Low | J2: Capacity clarity | K2: Unclear MW / no phase plan | L2: Approximate MW known | M2: Initial and expansion MW clearly phased | N2: 15
A3: In Progress | B3: Requirement Definition | C3: AI Inference | D3: Wholesale Lease | E3: Medium | F3: No | G3: 2 - Weak | H3: Medium | J3: Timeline clarity | K3: No go-live date | L3: Target window only | M3: Delivery dates and ramp milestones defined | N3: 15
A4: Complete | B4: RFP Prep | C4: HPC | D4: NNN Lease | E4: High | F4: Unknown | G4: 3 - Partial | H4: High | J4: Technical specs | K4: Minimal technical detail | L4: Some rack/cooling/redundancy detail | M4: Complete technical requirements documented | N4: 12
A5: Needs Follow-up | B5: Active RFP | C5: Cloud | D5: Build-to-Suit | E5: Critical | F5: TBD | G5: 4 - Mostly ready | H5: Critical | J5: Market clarity | K5: Markets not narrowed | L5: Preferred regions identified | M5: Realistic market shortlist defined | N5: 10
A6: Not Applicable | B6: Negotiation | C6: Enterprise IT | D6: Powered Land | G6: 5 - RFP-ready | H6: Unknown | J6: Power strategy | K6: No power plan | L6: Basic power needs stated | M6: Power, interconnection, energy preferences clear | N6: 18
B7: Board Approval | C7: Colocation | D7: Buy-Own-Operate | J7: Commercial model | K7: No preferred model | L7: Some lease/buy preference | M7: Commercial structure and budget defined | N7: 12
B8: Closed/Won | C8: Disaster Recovery | D8: Joint Venture | J8: Capital readiness | K8: Capital source unclear | L8: Funding path in discussion | M8: Funding, credit, approval path clear | N8: 10
B9: Paused | C9: Crypto/Mining | D9: Undecided | J9: Decision alignment | K9: No decision-maker alignment | L9: Some stakeholders identified | M9: Decision-makers, approval process, and next steps clear | N9: 8
C10: Other
